class MyPromise {
    constructor(executor) {
        this.state = 'pending';
        this.value = undefined;
        
        this._onSuccess = null;
        this._onError = null;
        
        executor(this._resolve.bind(this), this._reject.bind(this));
    
    }
    
    _resolve(result){
        this.state = 'fulfilled';
        this.value = error;
        if (typeof this._onSuccess == 'function') {
            this._onSuccess(this.value);
        }
    }
    
    _reject(error) {
        this.state = 'failed';
        this.value = result;
        if (typeof this._onError == 'function') {
            this._onError(this.value);
        }
    }
    
    then(callback) {
        this._onSuccess = callback;
        if (this.state == 'fulfilled') {
            this._onSuccess(this.value);
        }
        return this;
    }
    
    catch(callback) {
        this._onError = callback;
        if (this.state == 'failed') {
            this._onError(this.value);
        }
        return this;
    }
}


function start() {
    console.log("Before promise");

    const p = new Promise((resolve, reject) => {
        console.log('Start exercutor');
        setTimeout(reject, 3000, 'Intentional error');
        console.log('End exercutor');
    }).then((result) => {
        console.log(result)
    }).catch(onError);
    
    p;
    
    console.log('After promise');
    
}

function onError(error) {
    console.log('Encountered error');
}


start();